--------------------------------

The log includes a copy of your <USERNAME>.ini with
all usernames, passwords and API-keys removed.

--------------------------------
2023-04-30 16:20:45,141::INFO::[SABnzbd:1167] --------------------------------
2023-04-30 16:20:45,142::INFO::[SABnzbd:1168] SABnzbd.py-3.7.2
2023-04-30 16:20:45,142::INFO::[SABnzbd:1178] Commit = <HASH>1b7feddafc49d3b
2023-04-30 16:20:45,142::INFO::[SABnzbd:1180] Full executable path = /app/<USERNAME>/SABnzbd.py
2023-04-30 16:20:45,143::INFO::[SABnzbd:1181] Arguments = "/app/<USERNAME>/SABnzbd.py" "-f" "/app/<USERNAME>/.config/<USERNAME>.ini"
2023-04-30 16:20:45,143::INFO::[SABnzbd:1182] Python-version = 3.10.10 (main, Feb  9 2023, 02:08:14) [GCC 12.2.1 20220924]
2023-04-30 16:20:45,143::INFO::[SABnzbd:1183] Dockerized = True
2023-04-30 16:20:45,143::INFO::[SABnzbd:1184] CPU architecture = x86_64
2023-04-30 16:20:45,159::INFO::[SABnzbd:1187] Platform = posix - Linux-4.19.0-23-cloud-amd64-x86_64-with
2023-04-30 16:20:45,159::INFO::[SABnzbd:1193] Preferred encoding = UTF-8
2023-04-30 16:20:45,160::INFO::[SABnzbd:1215] SSL version = OpenSSL 3.0.8 7 Feb 2023
2023-04-30 16:20:45,160::INFO::[SABnzbd:1246] Using INI file /app/<USERNAME>/.config/<USERNAME>.ini
2023-04-30 16:20:45,161::INFO::[filesystem:701] Creating directories: /tmp/Downloads/complete
2023-04-30 16:20:45,161::INFO::[filesystem:701] Creating directories: /tmp/Downloads/incomplete
2023-04-30 16:20:45,162::INFO::[filesystem:1137] [N/A] /tmp/admin/totals10.sab missing
2023-04-30 16:20:45,213::INFO::[postproc:134] Loading postproc queue
2023-04-30 16:20:45,214::INFO::[filesystem:1137] [N/A] /tmp/admin/postproc2.sab missing
2023-04-30 16:20:45,215::INFO::[filesystem:1137] [N/A] /tmp/admin/watched_data2.sab missing
2023-04-30 16:20:45,216::INFO::[filesystem:1137] [N/A] /tmp/admin/rss_data.sab missing
2023-04-30 16:20:45,217::INFO::[scheduler:190] Scheduling RSS interval task every 60 min (delay=48)
2023-04-30 16:20:45,218::INFO::[scheduler:201] Scheduling VersionCheck on day 7 at 5:7
2023-04-30 16:20:45,218::INFO::[scheduler:215] Setting schedule for midnight BPS reset
2023-04-30 16:20:45,219::INFO::[scheduler:218] Setting schedule for server expiration check
2023-04-30 16:20:45,219::INFO::[scheduler:223] Setting schedule for server quota check
2023-04-30 16:20:45,220::INFO::[filesystem:1137] [N/A] /tmp/admin/queue10.sab missing
2023-04-30 16:20:45,220::INFO::[__init__:321] All processes started
2023-04-30 16:20:45,221::INFO::[SABnzbd:336] Template location for Glitter is /app/<USERNAME>/interfaces/Glitter
2023-04-30 16:20:45,221::INFO::[SABnzbd:336] Template location for Config is /app/<USERNAME>/interfaces/Config
2023-04-30 16:20:45,222::INFO::[misc:1166] [N/A] Running external command: ['/usr/bin/unrar']
2023-04-30 16:20:45,236::INFO::[misc:1166] [N/A] Running external command: ['/usr/bin/7za']
2023-04-30 16:20:45,251::INFO::[misc:1166] [N/A] Running external command: ['/usr/bin/par2', '-h']
2023-04-30 16:20:45,274::INFO::[SABnzbd:423] SABYenc module (v5.4.4)... found!
2023-04-30 16:20:45,275::INFO::[SABnzbd:424] SABYenc module is using SIMD set: AVX2
2023-04-30 16:20:45,275::INFO::[SABnzbd:443] Cryptography module (v39.0.0)... found!
2023-04-30 16:20:45,275::INFO::[SABnzbd:448] par2 binary... found (/usr/bin/par2)
2023-04-30 16:20:45,276::INFO::[SABnzbd:455] UNRAR binary... found (/usr/bin/unrar)
2023-04-30 16:20:45,276::INFO::[SABnzbd:463] UNRAR binary version 6.21
2023-04-30 16:20:45,276::INFO::[SABnzbd:471] 7za binary... found (/usr/bin/7za)
2023-04-30 16:20:45,277::INFO::[SABnzbd:473] 7za binary version 17.04
2023-04-30 16:20:45,277::INFO::[SABnzbd:484] nice binary... found (/bin/nice)
2023-04-30 16:20:45,277::INFO::[SABnzbd:488] ionice binary... found (/bin/ionice)
2023-04-30 16:20:45,279::INFO::[SABnzbd:1435] Starting web-interface on 0.0.0.0:8080
2023-04-30 16:20:45,279::INFO::[_cplogging:213] [30/Apr/2023:16:20:45] ENGINE Bus STARTING
2023-04-30 16:20:45,389::INFO::[_cplogging:213] [30/Apr/2023:16:20:45] ENGINE Serving on http://0.0.0.0:8080
2023-04-30 16:20:45,390::INFO::[_cplogging:213] [30/Apr/2023:16:20:45] ENGINE Bus STARTED
2023-04-30 16:20:45,391::INFO::[SABnzbd:1474] Starting SABnzbd.py-3.7.2
2023-04-30 16:20:45,394::INFO::[dirscanner:117] Dirscanner starting up
2023-04-30 16:20:45,395::INFO::[panic:239] Launching browser with http://127.0.0.1:8080/<USERNAME>
2023-04-30 16:20:45,397::INFO::[notifier:123] Sending notification: SABnzbd - SABnzbd 3.7.2 started (type=startup, job_cat=None)
2023-04-30 16:20:45,398::INFO::[database:558] Scheduled history purge
2023-04-30 16:20:45,786::INFO::[notifier:123] Sending notification: Update Available! - SABnzbd 4.0.0 (type=other, job_cat=None)
2023-04-30 16:20:45,787::INFO::[zconfig:61] No bonjour/zeroconf support installed
2023-04-30 16:20:45,788::INFO::[ssdp:108] Serving SSDP on 172.25.0.6 as SABnzbd
2023-05-02 17:02:34,539::INFO::[notifier:123] Sending notification: Error - Cannot create backup file for /app/<USERNAME>/.config/<USERNAME>.ini.bak (type=error, job_cat=None)
2023-05-02 17:02:34,539::ERROR::[config:901] Cannot create backup file for /app/<USERNAME>/.config/<USERNAME>.ini.bak
2023-05-02 17:02:34,543::INFO::[config:902] Traceback: 
Traceback (most recent call last):
  File "/app/<USERNAME>/<USERNAME>/config.py", line 897, in save_config
    shutil.copyfile(filename, bakname)
  File "/usr/lib/python3.10/shutil.py", line 256, in copyfile
    with open(dst, 'wb') as fdst:
PermissionError: [Errno 13] Permission denied: '/app/<USERNAME>/.config/<USERNAME>.ini.bak'
2023-05-02 17:02:34,556::ERROR::[config:901] Cannot create backup file for /app/<USERNAME>/.config/<USERNAME>.ini.bak
2023-05-02 17:02:34,556::INFO::[config:902] Traceback: 
Traceback (most recent call last):
  File "/app/<USERNAME>/<USERNAME>/config.py", line 897, in save_config
    shutil.copyfile(filename, bakname)
  File "/usr/lib/python3.10/shutil.py", line 256, in copyfile
    with open(dst, 'wb') as fdst:
PermissionError: [Errno 13] Permission denied: '/app/<USERNAME>/.config/<USERNAME>.ini.bak'
2023-05-02 17:02:34,561::ERROR::[config:901] Cannot create backup file for /app/<USERNAME>/.config/<USERNAME>.ini.bak
2023-05-02 17:02:34,561::INFO::[config:902] Traceback: 
Traceback (most recent call last):
  File "/app/<USERNAME>/<USERNAME>/config.py", line 897, in save_config
    shutil.copyfile(filename, bakname)
  File "/usr/lib/python3.10/shutil.py", line 256, in copyfile
    with open(dst, 'wb') as fdst:
PermissionError: [Errno 13] Permission denied: '/app/<USERNAME>/.config/<USERNAME>.ini.bak'
2023-05-02 17:02:46,067::ERROR::[config:901] Cannot create backup file for /app/<USERNAME>/.config/<USERNAME>.ini.bak
2023-05-02 17:02:46,067::INFO::[config:902] Traceback: 
Traceback (most recent call last):
  File "/app/<USERNAME>/<USERNAME>/config.py", line 897, in save_config
    shutil.copyfile(filename, bakname)
  File "/usr/lib/python3.10/shutil.py", line 256, in copyfile
    with open(dst, 'wb') as fdst:
PermissionError: [Errno 13] Permission denied: '/app/<USERNAME>/.config/<USERNAME>.ini.bak'
2023-05-02 17:03:16,075::ERROR::[config:901] Cannot create backup file for /app/<USERNAME>/.config/<USERNAME>.ini.bak
2023-05-02 17:03:16,075::INFO::[config:902] Traceback: 
Traceback (most recent call last):
  File "/app/<USERNAME>/<USERNAME>/config.py", line 897, in save_config
    shutil.copyfile(filename, bakname)
  File "/usr/lib/python3.10/shutil.py", line 256, in copyfile
    with open(dst, 'wb') as fdst:
PermissionError: [Errno 13] Permission denied: '/app/<USERNAME>/.config/<USERNAME>.ini.bak'
2023-05-02 17:03:46,082::ERROR::[config:901] Cannot create backup file for /app/<USERNAME>/.config/<USERNAME>.ini.bak
2023-05-02 17:03:46,082::INFO::[config:902] Traceback: 
Traceback (most recent call last):
  File "/app/<USERNAME>/<USERNAME>/config.py", line 897, in save_config
    shutil.copyfile(filename, bakname)
  File "/usr/lib/python3.10/shutil.py", line 256, in copyfile
    with open(dst, 'wb') as fdst:
PermissionError: [Errno 13] Permission denied: '/app/<USERNAME>/.config/<USERNAME>.ini.bak'
2023-05-02 17:04:16,091::ERROR::[config:901] Cannot create backup file for /app/<USERNAME>/.config/<USERNAME>.ini.bak
2023-05-02 17:04:16,091::INFO::[config:902] Traceback: 
Traceback (most recent call last):
  File "/app/<USERNAME>/<USERNAME>/config.py", line 897, in save_config
    shutil.copyfile(filename, bakname)
  File "/usr/lib/python3.10/shutil.py", line 256, in copyfile
    with open(dst, 'wb') as fdst:
PermissionError: [Errno 13] Permission denied: '/app/<USERNAME>/.config/<USERNAME>.ini.bak'
2023-05-02 17:04:46,097::ERROR::[config:901] Cannot create backup file for /app/<USERNAME>/.config/<USERNAME>.ini.bak
2023-05-02 17:04:46,097::INFO::[config:902] Traceback: 
Traceback (most recent call last):
  File "/app/<USERNAME>/<USERNAME>/config.py", line 897, in save_config
    shutil.copyfile(filename, bakname)
  File "/usr/lib/python3.10/shutil.py", line 256, in copyfile
    with open(dst, 'wb') as fdst:
PermissionError: [Errno 13] Permission denied: '/app/<USERNAME>/.config/<USERNAME>.ini.bak'
2023-05-02 17:05:16,103::ERROR::[config:901] Cannot create backup file for /app/<USERNAME>/.config/<USERNAME>.ini.bak
2023-05-02 17:05:16,103::INFO::[config:902] Traceback: 
Traceback (most recent call last):
  File "/app/<USERNAME>/<USERNAME>/config.py", line 897, in save_config
    shutil.copyfile(filename, bakname)
  File "/usr/lib/python3.10/shutil.py", line 256, in copyfile
    with open(dst, 'wb') as fdst:
PermissionError: [Errno 13] Permission denied: '/app/<USERNAME>/.config/<USERNAME>.ini.bak'
2023-05-02 17:05:46,109::ERROR::[config:901] Cannot create backup file for /app/<USERNAME>/.config/<USERNAME>.ini.bak
2023-05-02 17:05:46,110::INFO::[config:902] Traceback: 
Traceback (most recent call last):
  File "/app/<USERNAME>/<USERNAME>/config.py", line 897, in save_config
    shutil.copyfile(filename, bakname)
  File "/usr/lib/python3.10/shutil.py", line 256, in copyfile
    with open(dst, 'wb') as fdst:
PermissionError: [Errno 13] Permission denied: '/app/<USERNAME>/.config/<USERNAME>.ini.bak'
2023-05-02 17:06:16,143::ERROR::[config:901] Cannot create backup file for /app/<USERNAME>/.config/<USERNAME>.ini.bak
2023-05-02 17:06:16,144::INFO::[config:902] Traceback: 
Traceback (most recent call last):
  File "/app/<USERNAME>/<USERNAME>/config.py", line 897, in save_config
    shutil.copyfile(filename, bakname)
  File "/usr/lib/python3.10/shutil.py", line 256, in copyfile
    with open(dst, 'wb') as fdst:
PermissionError: [Errno 13] Permission denied: '/app/<USERNAME>/.config/<USERNAME>.ini.bak'
2023-05-02 17:06:46,148::ERROR::[config:901] Cannot create backup file for /app/<USERNAME>/.config/<USERNAME>.ini.bak
2023-05-02 17:06:46,149::INFO::[config:902] Traceback: 
Traceback (most recent call last):
  File "/app/<USERNAME>/<USERNAME>/config.py", line 897, in save_config
    shutil.copyfile(filename, bakname)
  File "/usr/lib/python3.10/shutil.py", line 256, in copyfile
    with open(dst, 'wb') as fdst:
PermissionError: [Errno 13] Permission denied: '/app/<USERNAME>/.config/<USERNAME>.ini.bak'
2023-05-02 17:07:16,154::ERROR::[config:901] Cannot create backup file for /app/<USERNAME>/.config/<USERNAME>.ini.bak
2023-05-02 17:07:16,155::INFO::[config:902] Traceback: 
Traceback (most recent call last):
  File "/app/<USERNAME>/<USERNAME>/config.py", line 897, in save_config
    shutil.copyfile(filename, bakname)
  File "/usr/lib/python3.10/shutil.py", line 256, in copyfile
    with open(dst, 'wb') as fdst:
PermissionError: [Errno 13] Permission denied: '/app/<USERNAME>/.config/<USERNAME>.ini.bak'
2023-05-02 17:07:46,162::ERROR::[config:901] Cannot create backup file for /app/<USERNAME>/.config/<USERNAME>.ini.bak
2023-05-02 17:07:46,162::INFO::[config:902] Traceback: 
Traceback (most recent call last):
  File "/app/<USERNAME>/<USERNAME>/config.py", line 897, in save_config
    shutil.copyfile(filename, bakname)
  File "/usr/lib/python3.10/shutil.py", line 256, in copyfile
    with open(dst, 'wb') as fdst:
PermissionError: [Errno 13] Permission denied: '/app/<USERNAME>/.config/<USERNAME>.ini.bak'
2023-05-02 17:08:16,170::ERROR::[config:901] Cannot create backup file for /app/<USERNAME>/.config/<USERNAME>.ini.bak
2023-05-02 17:08:16,170::INFO::[config:902] Traceback: 
Traceback (most recent call last):
  File "/app/<USERNAME>/<USERNAME>/config.py", line 897, in save_config
    shutil.copyfile(filename, bakname)
  File "/usr/lib/python3.10/shutil.py", line 256, in copyfile
    with open(dst, 'wb') as fdst:
PermissionError: [Errno 13] Permission denied: '/app/<USERNAME>/.config/<USERNAME>.ini.bak'
2023-05-02 17:08:46,177::ERROR::[config:901] Cannot create backup file for /app/<USERNAME>/.config/<USERNAME>.ini.bak
2023-05-02 17:08:46,177::INFO::[config:902] Traceback: 
Traceback (most recent call last):
  File "/app/<USERNAME>/<USERNAME>/config.py", line 897, in save_config
    shutil.copyfile(filename, bakname)
  File "/usr/lib/python3.10/shutil.py", line 256, in copyfile
    with open(dst, 'wb') as fdst:
PermissionError: [Errno 13] Permission denied: '/app/<USERNAME>/.config/<USERNAME>.ini.bak'
2023-05-02 17:09:16,184::ERROR::[config:901] Cannot create backup file for /app/<USERNAME>/.config/<USERNAME>.ini.bak
2023-05-02 17:09:16,185::INFO::[config:902] Traceback: 
Traceback (most recent call last):
  File "/app/<USERNAME>/<USERNAME>/config.py", line 897, in save_config
    shutil.copyfile(filename, bakname)
  File "/usr/lib/python3.10/shutil.py", line 256, in copyfile
    with open(dst, 'wb') as fdst:
PermissionError: [Errno 13] Permission denied: '/app/<USERNAME>/.config/<USERNAME>.ini.bak'
2023-05-02 17:09:46,191::ERROR::[config:901] Cannot create backup file for /app/<USERNAME>/.config/<USERNAME>.ini.bak
2023-05-02 17:09:46,192::INFO::[config:902] Traceback: 
Traceback (most recent call last):
  File "/app/<USERNAME>/<USERNAME>/config.py", line 897, in save_config
    shutil.copyfile(filename, bakname)
  File "/usr/lib/python3.10/shutil.py", line 256, in copyfile
    with open(dst, 'wb') as fdst:
PermissionError: [Errno 13] Permission denied: '/app/<USERNAME>/.config/<USERNAME>.ini.bak'
2023-05-02 17:10:16,199::ERROR::[config:901] Cannot create backup file for /app/<USERNAME>/.config/<USERNAME>.ini.bak
2023-05-02 17:10:16,200::INFO::[config:902] Traceback: 
Traceback (most recent call last):
  File "/app/<USERNAME>/<USERNAME>/config.py", line 897, in save_config
    shutil.copyfile(filename, bakname)
  File "/usr/lib/python3.10/shutil.py", line 256, in copyfile
    with open(dst, 'wb') as fdst:
PermissionError: [Errno 13] Permission denied: '/app/<USERNAME>/.config/<USERNAME>.ini.bak'
2023-05-02 17:10:46,208::ERROR::[config:901] Cannot create backup file for /app/<USERNAME>/.config/<USERNAME>.ini.bak
2023-05-02 17:10:46,208::INFO::[config:902] Traceback: 
Traceback (most recent call last):
  File "/app/<USERNAME>/<USERNAME>/config.py", line 897, in save_config
    shutil.copyfile(filename, bakname)
  File "/usr/lib/python3.10/shutil.py", line 256, in copyfile
    with open(dst, 'wb') as fdst:
PermissionError: [Errno 13] Permission denied: '/app/<USERNAME>/.config/<USERNAME>.ini.bak'
2023-05-02 17:11:16,243::ERROR::[config:901] Cannot create backup file for /app/<USERNAME>/.config/<USERNAME>.ini.bak
2023-05-02 17:11:16,244::INFO::[config:902] Traceback: 
Traceback (most recent call last):
  File "/app/<USERNAME>/<USERNAME>/config.py", line 897, in save_config
    shutil.copyfile(filename, bakname)
  File "/usr/lib/python3.10/shutil.py", line 256, in copyfile
    with open(dst, 'wb') as fdst:
PermissionError: [Errno 13] Permission denied: '/app/<USERNAME>/.config/<USERNAME>.ini.bak'
2023-05-02 17:11:46,251::ERROR::[config:901] Cannot create backup file for /app/<USERNAME>/.config/<USERNAME>.ini.bak
2023-05-02 17:11:46,252::INFO::[config:902] Traceback: 
Traceback (most recent call last):
  File "/app/<USERNAME>/<USERNAME>/config.py", line 897, in save_config
    shutil.copyfile(filename, bakname)
  File "/usr/lib/python3.10/shutil.py", line 256, in copyfile
    with open(dst, 'wb') as fdst:
PermissionError: [Errno 13] Permission denied: '/app/<USERNAME>/.config/<USERNAME>.ini.bak'
2023-05-02 17:12:16,259::ERROR::[config:901] Cannot create backup file for /app/<USERNAME>/.config/<USERNAME>.ini.bak
2023-05-02 17:12:16,260::INFO::[config:902] Traceback: 
Traceback (most recent call last):
  File "/app/<USERNAME>/<USERNAME>/config.py", line 897, in save_config
    shutil.copyfile(filename, bakname)
  File "/usr/lib/python3.10/shutil.py", line 256, in copyfile
    with open(dst, 'wb') as fdst:
PermissionError: [Errno 13] Permission denied: '/app/<USERNAME>/.config/<USERNAME>.ini.bak'
2023-05-02 17:12:46,267::ERROR::[config:901] Cannot create backup file for /app/<USERNAME>/.config/<USERNAME>.ini.bak
2023-05-02 17:12:46,267::INFO::[config:902] Traceback: 
Traceback (most recent call last):
  File "/app/<USERNAME>/<USERNAME>/config.py", line 897, in save_config
    shutil.copyfile(filename, bakname)
  File "/usr/lib/python3.10/shutil.py", line 256, in copyfile
    with open(dst, 'wb') as fdst:
PermissionError: [Errno 13] Permission denied: '/app/<USERNAME>/.config/<USERNAME>.ini.bak'
2023-05-02 17:13:16,274::ERROR::[config:901] Cannot create backup file for /app/<USERNAME>/.config/<USERNAME>.ini.bak
2023-05-02 17:13:16,275::INFO::[config:902] Traceback: 
Traceback (most recent call last):
  File "/app/<USERNAME>/<USERNAME>/config.py", line 897, in save_config
    shutil.copyfile(filename, bakname)
  File "/usr/lib/python3.10/shutil.py", line 256, in copyfile
    with open(dst, 'wb') as fdst:
PermissionError: [Errno 13] Permission denied: '/app/<USERNAME>/.config/<USERNAME>.ini.bak'
2023-05-02 17:13:46,282::ERROR::[config:901] Cannot create backup file for /app/<USERNAME>/.config/<USERNAME>.ini.bak
2023-05-02 17:13:46,283::INFO::[config:902] Traceback: 
Traceback (most recent call last):
  File "/app/<USERNAME>/<USERNAME>/config.py", line 897, in save_config
    shutil.copyfile(filename, bakname)
  File "/usr/lib/python3.10/shutil.py", line 256, in copyfile
    with open(dst, 'wb') as fdst:
PermissionError: [Errno 13] Permission denied: '/app/<USERNAME>/.config/<USERNAME>.ini.bak'
2023-05-02 17:14:16,289::ERROR::[config:901] Cannot create backup file for /app/<USERNAME>/.config/<USERNAME>.ini.bak
2023-05-02 17:14:16,290::INFO::[config:902] Traceback: 
Traceback (most recent call last):
  File "/app/<USERNAME>/<USERNAME>/config.py", line 897, in save_config
    shutil.copyfile(filename, bakname)
  File "/usr/lib/python3.10/shutil.py", line 256, in copyfile
    with open(dst, 'wb') as fdst:
PermissionError: [Errno 13] Permission denied: '/app/<USERNAME>/.config/<USERNAME>.ini.bak'
2023-05-02 17:14:46,297::ERROR::[config:901] Cannot create backup file for /app/<USERNAME>/.config/<USERNAME>.ini.bak
2023-05-02 17:14:46,298::INFO::[config:902] Traceback: 
Traceback (most recent call last):
  File "/app/<USERNAME>/<USERNAME>/config.py", line 897, in save_config
    shutil.copyfile(filename, bakname)
  File "/usr/lib/python3.10/shutil.py", line 256, in copyfile
    with open(dst, 'wb') as fdst:
PermissionError: [Errno 13] Permission denied: '/app/<USERNAME>/.config/<USERNAME>.ini.bak'
2023-05-02 17:15:16,305::ERROR::[config:901] Cannot create backup file for /app/<USERNAME>/.config/<USERNAME>.ini.bak
2023-05-02 17:15:16,306::INFO::[config:902] Traceback: 
Traceback (most recent call last):
  File "/app/<USERNAME>/<USERNAME>/config.py", line 897, in save_config
    shutil.copyfile(filename, bakname)
  File "/usr/lib/python3.10/shutil.py", line 256, in copyfile
    with open(dst, 'wb') as fdst:
PermissionError: [Errno 13] Permission denied: '/app/<USERNAME>/.config/<USERNAME>.ini.bak'
2023-05-02 17:15:46,313::ERROR::[config:901] Cannot create backup file for /app/<USERNAME>/.config/<USERNAME>.ini.bak
2023-05-02 17:15:46,314::INFO::[config:902] Traceback: 
Traceback (most recent call last):
  File "/app/<USERNAME>/<USERNAME>/config.py", line 897, in save_config
    shutil.copyfile(filename, bakname)
  File "/usr/lib/python3.10/shutil.py", line 256, in copyfile
    with open(dst, 'wb') as fdst:
PermissionError: [Errno 13] Permission denied: '/app/<USERNAME>/.config/<USERNAME>.ini.bak'
2023-05-02 17:16:16,353::ERROR::[config:901] Cannot create backup file for /app/<USERNAME>/.config/<USERNAME>.ini.bak
2023-05-02 17:16:16,353::INFO::[config:902] Traceback: 
Traceback (most recent call last):
  File "/app/<USERNAME>/<USERNAME>/config.py", line 897, in save_config
    shutil.copyfile(filename, bakname)
  File "/usr/lib/python3.10/shutil.py", line 256, in copyfile
    with open(dst, 'wb') as fdst:
PermissionError: [Errno 13] Permission denied: '/app/<USERNAME>/.config/<USERNAME>.ini.bak'
2023-05-02 17:16:46,360::ERROR::[config:901] Cannot create backup file for /app/<USERNAME>/.config/<USERNAME>.ini.bak
2023-05-02 17:16:46,361::INFO::[config:902] Traceback: 
Traceback (most recent call last):
  File "/app/<USERNAME>/<USERNAME>/config.py", line 897, in save_config
    shutil.copyfile(filename, bakname)
  File "/usr/lib/python3.10/shutil.py", line 256, in copyfile
    with open(dst, 'wb') as fdst:
PermissionError: [Errno 13] Permission denied: '/app/<USERNAME>/.config/<USERNAME>.ini.bak'
2023-05-02 17:17:16,366::ERROR::[config:901] Cannot create backup file for /app/<USERNAME>/.config/<USERNAME>.ini.bak
2023-05-02 17:17:16,366::INFO::[config:902] Traceback: 
Traceback (most recent call last):
  File "/app/<USERNAME>/<USERNAME>/config.py", line 897, in save_config
    shutil.copyfile(filename, bakname)
  File "/usr/lib/python3.10/shutil.py", line 256, in copyfile
    with open(dst, 'wb') as fdst:
PermissionError: [Errno 13] Permission denied: '/app/<USERNAME>/.config/<USERNAME>.ini.bak'
2023-05-02 17:17:46,373::ERROR::[config:901] Cannot create backup file for /app/<USERNAME>/.config/<USERNAME>.ini.bak
2023-05-02 17:17:46,374::INFO::[config:902] Traceback: 
Traceback (most recent call last):
  File "/app/<USERNAME>/<USERNAME>/config.py", line 897, in save_config
    shutil.copyfile(filename, bakname)
  File "/usr/lib/python3.10/shutil.py", line 256, in copyfile
    with open(dst, 'wb') as fdst:
PermissionError: [Errno 13] Permission denied: '/app/<USERNAME>/.config/<USERNAME>.ini.bak'
2023-05-02 17:18:16,380::ERROR::[config:901] Cannot create backup file for /app/<USERNAME>/.config/<USERNAME>.ini.bak
2023-05-02 17:18:16,381::INFO::[config:902] Traceback: 
Traceback (most recent call last):
  File "/app/<USERNAME>/<USERNAME>/config.py", line 897, in save_config
    shutil.copyfile(filename, bakname)
  File "/usr/lib/python3.10/shutil.py", line 256, in copyfile
    with open(dst, 'wb') as fdst:
PermissionError: [Errno 13] Permission denied: '/app/<USERNAME>/.config/<USERNAME>.ini.bak'
2023-05-02 17:18:46,387::ERROR::[config:901] Cannot create backup file for /app/<USERNAME>/.config/<USERNAME>.ini.bak
2023-05-02 17:18:46,388::INFO::[config:902] Traceback: 
Traceback (most recent call last):
  File "/app/<USERNAME>/<USERNAME>/config.py", line 897, in save_config
    shutil.copyfile(filename, bakname)
  File "/usr/lib/python3.10/shutil.py", line 256, in copyfile
    with open(dst, 'wb') as fdst:
PermissionError: [Errno 13] Permission denied: '/app/<USERNAME>/.config/<USERNAME>.ini.bak'
2023-05-02 17:19:16,394::ERROR::[config:901] Cannot create backup file for /app/<USERNAME>/.config/<USERNAME>.ini.bak
2023-05-02 17:19:16,395::INFO::[config:902] Traceback: 
Traceback (most recent call last):
  File "/app/<USERNAME>/<USERNAME>/config.py", line 897, in save_config
    shutil.copyfile(filename, bakname)
  File "/usr/lib/python3.10/shutil.py", line 256, in copyfile
    with open(dst, 'wb') as fdst:
PermissionError: [Errno 13] Permission denied: '/app/<USERNAME>/.config/<USERNAME>.ini.bak'
2023-05-02 17:19:46,402::ERROR::[config:901] Cannot create backup file for /app/<USERNAME>/.config/<USERNAME>.ini.bak
2023-05-02 17:19:46,402::INFO::[config:902] Traceback: 
Traceback (most recent call last):
  File "/app/<USERNAME>/<USERNAME>/config.py", line 897, in save_config
    shutil.copyfile(filename, bakname)
  File "/usr/lib/python3.10/shutil.py", line 256, in copyfile
    with open(dst, 'wb') as fdst:
PermissionError: [Errno 13] Permission denied: '/app/<USERNAME>/.config/<USERNAME>.ini.bak'
2023-05-02 17:20:16,409::ERROR::[config:901] Cannot create backup file for /app/<USERNAME>/.config/<USERNAME>.ini.bak
2023-05-02 17:20:16,410::INFO::[config:902] Traceback: 
Traceback (most recent call last):
  File "/app/<USERNAME>/<USERNAME>/config.py", line 897, in save_config
    shutil.copyfile(filename, bakname)
  File "/usr/lib/python3.10/shutil.py", line 256, in copyfile
    with open(dst, 'wb') as fdst:
PermissionError: [Errno 13] Permission denied: '/app/<USERNAME>/.config/<USERNAME>.ini.bak'
2023-05-02 17:20:46,417::ERROR::[config:901] Cannot create backup file for /app/<USERNAME>/.config/<USERNAME>.ini.bak
2023-05-02 17:20:46,417::INFO::[config:902] Traceback: 
Traceback (most recent call last):
  File "/app/<USERNAME>/<USERNAME>/config.py", line 897, in save_config
    shutil.copyfile(filename, bakname)
  File "/usr/lib/python3.10/shutil.py", line 256, in copyfile
    with open(dst, 'wb') as fdst:
PermissionError: [Errno 13] Permission denied: '/app/<USERNAME>/.config/<USERNAME>.ini.bak'
2023-05-02 17:21:16,453::ERROR::[config:901] Cannot create backup file for /app/<USERNAME>/.config/<USERNAME>.ini.bak
2023-05-02 17:21:16,454::INFO::[config:902] Traceback: 
Traceback (most recent call last):
  File "/app/<USERNAME>/<USERNAME>/config.py", line 897, in save_config
    shutil.copyfile(filename, bakname)
  File "/usr/lib/python3.10/shutil.py", line 256, in copyfile
    with open(dst, 'wb') as fdst:
PermissionError: [Errno 13] Permission denied: '/app/<USERNAME>/.config/<USERNAME>.ini.bak'
2023-05-02 17:21:46,460::ERROR::[config:901] Cannot create backup file for /app/<USERNAME>/.config/<USERNAME>.ini.bak
2023-05-02 17:21:46,461::INFO::[config:902] Traceback: 
Traceback (most recent call last):
  File "/app/<USERNAME>/<USERNAME>/config.py", line 897, in save_config
    shutil.copyfile(filename, bakname)
  File "/usr/lib/python3.10/shutil.py", line 256, in copyfile
    with open(dst, 'wb') as fdst:
PermissionError: [Errno 13] Permission denied: '/app/<USERNAME>/.config/<USERNAME>.ini.bak'
2023-05-02 17:22:16,468::ERROR::[config:901] Cannot create backup file for /app/<USERNAME>/.config/<USERNAME>.ini.bak
2023-05-02 17:22:16,468::INFO::[config:902] Traceback: 
Traceback (most recent call last):
  File "/app/<USERNAME>/<USERNAME>/config.py", line 897, in save_config
    shutil.copyfile(filename, bakname)
  File "/usr/lib/python3.10/shutil.py", line 256, in copyfile
    with open(dst, 'wb') as fdst:
PermissionError: [Errno 13] Permission denied: '/app/<USERNAME>/.config/<USERNAME>.ini.bak'
2023-05-02 17:22:46,476::ERROR::[config:901] Cannot create backup file for /app/<USERNAME>/.config/<USERNAME>.ini.bak
2023-05-02 17:22:46,477::INFO::[config:902] Traceback: 
Traceback (most recent call last):
  File "/app/<USERNAME>/<USERNAME>/config.py", line 897, in save_config
    shutil.copyfile(filename, bakname)
  File "/usr/lib/python3.10/shutil.py", line 256, in copyfile
    with open(dst, 'wb') as fdst:
PermissionError: [Errno 13] Permission denied: '/app/<USERNAME>/.config/<USERNAME>.ini.bak'
2023-05-02 17:23:16,483::ERROR::[config:901] Cannot create backup file for /app/<USERNAME>/.config/<USERNAME>.ini.bak
2023-05-02 17:23:16,484::INFO::[config:902] Traceback: 
Traceback (most recent call last):
  File "/app/<USERNAME>/<USERNAME>/config.py", line 897, in save_config
    shutil.copyfile(filename, bakname)
  File "/usr/lib/python3.10/shutil.py", line 256, in copyfile
    with open(dst, 'wb') as fdst:
PermissionError: [Errno 13] Permission denied: '/app/<USERNAME>/.config/<USERNAME>.ini.bak'
2023-05-02 17:23:46,491::ERROR::[config:901] Cannot create backup file for /app/<USERNAME>/.config/<USERNAME>.ini.bak
2023-05-02 17:23:46,492::INFO::[config:902] Traceback: 
Traceback (most recent call last):
  File "/app/<USERNAME>/<USERNAME>/config.py", line 897, in save_config
    shutil.copyfile(filename, bakname)
  File "/usr/lib/python3.10/shutil.py", line 256, in copyfile
    with open(dst, 'wb') as fdst:
PermissionError: [Errno 13] Permission denied: '/app/<USERNAME>/.config/<USERNAME>.ini.bak'
2023-05-02 17:24:16,499::ERROR::[config:901] Cannot create backup file for /app/<USERNAME>/.config/<USERNAME>.ini.bak
2023-05-02 17:24:16,499::INFO::[config:902] Traceback: 
Traceback (most recent call last):
  File "/app/<USERNAME>/<USERNAME>/config.py", line 897, in save_config
    shutil.copyfile(filename, bakname)
  File "/usr/lib/python3.10/shutil.py", line 256, in copyfile
    with open(dst, 'wb') as fdst:
PermissionError: [Errno 13] Permission denied: '/app/<USERNAME>/.config/<USERNAME>.ini.bak'
2023-05-02 17:24:46,506::ERROR::[config:901] Cannot create backup file for /app/<USERNAME>/.config/<USERNAME>.ini.bak
2023-05-02 17:24:46,507::INFO::[config:902] Traceback: 
Traceback (most recent call last):
  File "/app/<USERNAME>/<USERNAME>/config.py", line 897, in save_config
    shutil.copyfile(filename, bakname)
  File "/usr/lib/python3.10/shutil.py", line 256, in copyfile
    with open(dst, 'wb') as fdst:
PermissionError: [Errno 13] Permission denied: '/app/<USERNAME>/.config/<USERNAME>.ini.bak'
2023-05-02 17:25:16,514::ERROR::[config:901] Cannot create backup file for /app/<USERNAME>/.config/<USERNAME>.ini.bak
2023-05-02 17:25:16,514::INFO::[config:902] Traceback: 
Traceback (most recent call last):
  File "/app/<USERNAME>/<USERNAME>/config.py", line 897, in save_config
    shutil.copyfile(filename, bakname)
  File "/usr/lib/python3.10/shutil.py", line 256, in copyfile
    with open(dst, 'wb') as fdst:
PermissionError: [Errno 13] Permission denied: '/app/<USERNAME>/.config/<USERNAME>.ini.bak'
2023-05-02 17:25:46,521::ERROR::[config:901] Cannot create backup file for /app/<USERNAME>/.config/<USERNAME>.ini.bak
2023-05-02 17:25:46,522::INFO::[config:902] Traceback: 
Traceback (most recent call last):
  File "/app/<USERNAME>/<USERNAME>/config.py", line 897, in save_config
    shutil.copyfile(filename, bakname)
  File "/usr/lib/python3.10/shutil.py", line 256, in copyfile
    with open(dst, 'wb') as fdst:
PermissionError: [Errno 13] Permission denied: '/app/<USERNAME>/.config/<USERNAME>.ini.bak'
2023-05-02 17:26:16,558::ERROR::[config:901] Cannot create backup file for /app/<USERNAME>/.config/<USERNAME>.ini.bak
2023-05-02 17:26:16,559::INFO::[config:902] Traceback: 
Traceback (most recent call last):
  File "/app/<USERNAME>/<USERNAME>/config.py", line 897, in save_config
    shutil.copyfile(filename, bakname)
  File "/usr/lib/python3.10/shutil.py", line 256, in copyfile
    with open(dst, 'wb') as fdst:
PermissionError: [Errno 13] Permission denied: '/app/<USERNAME>/.config/<USERNAME>.ini.bak'
2023-05-02 17:26:46,566::ERROR::[config:901] Cannot create backup file for /app/<USERNAME>/.config/<USERNAME>.ini.bak
2023-05-02 17:26:46,566::INFO::[config:902] Traceback: 
Traceback (most recent call last):
  File "/app/<USERNAME>/<USERNAME>/config.py", line 897, in save_config
    shutil.copyfile(filename, bakname)
  File "/usr/lib/python3.10/shutil.py", line 256, in copyfile
    with open(dst, 'wb') as fdst:
PermissionError: [Errno 13] Permission denied: '/app/<USERNAME>/.config/<USERNAME>.ini.bak'
2023-05-02 17:27:16,573::ERROR::[config:901] Cannot create backup file for /app/<USERNAME>/.config/<USERNAME>.ini.bak
2023-05-02 17:27:16,574::INFO::[config:902] Traceback: 
Traceback (most recent call last):
  File "/app/<USERNAME>/<USERNAME>/config.py", line 897, in save_config
    shutil.copyfile(filename, bakname)
  File "/usr/lib/python3.10/shutil.py", line 256, in copyfile
    with open(dst, 'wb') as fdst:
PermissionError: [Errno 13] Permission denied: '/app/<USERNAME>/.config/<USERNAME>.ini.bak'
2023-05-02 17:27:46,581::ERROR::[config:901] Cannot create backup file for /app/<USERNAME>/.config/<USERNAME>.ini.bak
2023-05-02 17:27:46,581::INFO::[config:902] Traceback: 
Traceback (most recent call last):
  File "/app/<USERNAME>/<USERNAME>/config.py", line 897, in save_config
    shutil.copyfile(filename, bakname)
  File "/usr/lib/python3.10/shutil.py", line 256, in copyfile
    with open(dst, 'wb') as fdst:
PermissionError: [Errno 13] Permission denied: '/app/<USERNAME>/.config/<USERNAME>.ini.bak'
2023-05-02 17:28:16,589::ERROR::[config:901] Cannot create backup file for /app/<USERNAME>/.config/<USERNAME>.ini.bak
2023-05-02 17:28:16,590::INFO::[config:902] Traceback: 
Traceback (most recent call last):
  File "/app/<USERNAME>/<USERNAME>/config.py", line 897, in save_config
    shutil.copyfile(filename, bakname)
  File "/usr/lib/python3.10/shutil.py", line 256, in copyfile
    with open(dst, 'wb') as fdst:
PermissionError: [Errno 13] Permission denied: '/app/<USERNAME>/.config/<USERNAME>.ini.bak'
2023-05-02 17:28:46,597::ERROR::[config:901] Cannot create backup file for /app/<USERNAME>/.config/<USERNAME>.ini.bak
2023-05-02 17:28:46,598::INFO::[config:902] Traceback: 
Traceback (most recent call last):
  File "/app/<USERNAME>/<USERNAME>/config.py", line 897, in save_config
    shutil.copyfile(filename, bakname)
  File "/usr/lib/python3.10/shutil.py", line 256, in copyfile
    with open(dst, 'wb') as fdst:
PermissionError: [Errno 13] Permission denied: '/app/<USERNAME>/.config/<USERNAME>.ini.bak'
2023-05-02 17:29:16,605::ERROR::[config:901] Cannot create backup file for /app/<USERNAME>/.config/<USERNAME>.ini.bak
2023-05-02 17:29:16,605::INFO::[config:902] Traceback: 
Traceback (most recent call last):
  File "/app/<USERNAME>/<USERNAME>/config.py", line 897, in save_config
    shutil.copyfile(filename, bakname)
  File "/usr/lib/python3.10/shutil.py", line 256, in copyfile
    with open(dst, 'wb') as fdst:
PermissionError: [Errno 13] Permission denied: '/app/<USERNAME>/.config/<USERNAME>.ini.bak'
2023-05-02 17:29:46,610::ERROR::[config:901] Cannot create backup file for /app/<USERNAME>/.config/<USERNAME>.ini.bak
2023-05-02 17:29:46,610::INFO::[config:902] Traceback: 
Traceback (most recent call last):
  File "/app/<USERNAME>/<USERNAME>/config.py", line 897, in save_config
    shutil.copyfile(filename, bakname)
  File "/usr/lib/python3.10/shutil.py", line 256, in copyfile
    with open(dst, 'wb') as fdst:
PermissionError: [Errno 13] Permission denied: '/app/<USERNAME>/.config/<USERNAME>.ini.bak'
2023-05-02 17:30:16,617::ERROR::[config:901] Cannot create backup file for /app/<USERNAME>/.config/<USERNAME>.ini.bak
2023-05-02 17:30:16,618::INFO::[config:902] Traceback: 
Traceback (most recent call last):
  File "/app/<USERNAME>/<USERNAME>/config.py", line 897, in save_config
    shutil.copyfile(filename, bakname)
  File "/usr/lib/python3.10/shutil.py", line 256, in copyfile
    with open(dst, 'wb') as fdst:
PermissionError: [Errno 13] Permission denied: '/app/<USERNAME>/.config/<USERNAME>.ini.bak'
2023-05-02 17:30:46,624::ERROR::[config:901] Cannot create backup file for /app/<USERNAME>/.config/<USERNAME>.ini.bak
2023-05-02 17:30:46,625::INFO::[config:902] Traceback: 
Traceback (most recent call last):
  File "/app/<USERNAME>/<USERNAME>/config.py", line 897, in save_config
    shutil.copyfile(filename, bakname)
  File "/usr/lib/python3.10/shutil.py", line 256, in copyfile
    with open(dst, 'wb') as fdst:
PermissionError: [Errno 13] Permission denied: '/app/<USERNAME>/.config/<USERNAME>.ini.bak'
2023-05-02 17:31:16,661::ERROR::[config:901] Cannot create backup file for /app/<USERNAME>/.config/<USERNAME>.ini.bak
2023-05-02 17:31:16,662::INFO::[config:902] Traceback: 
Traceback (most recent call last):
  File "/app/<USERNAME>/<USERNAME>/config.py", line 897, in save_config
    shutil.copyfile(filename, bakname)
  File "/usr/lib/python3.10/shutil.py", line 256, in copyfile
    with open(dst, 'wb') as fdst:
PermissionError: [Errno 13] Permission denied: '/app/<USERNAME>/.config/<USERNAME>.ini.bak'
2023-05-02 17:31:46,667::ERROR::[config:901] Cannot create backup file for /app/<USERNAME>/.config/<USERNAME>.ini.bak
2023-05-02 17:31:46,667::INFO::[config:902] Traceback: 
Traceback (most recent call last):
  File "/app/<USERNAME>/<USERNAME>/config.py", line 897, in save_config
    shutil.copyfile(filename, bakname)
  File "/usr/lib/python3.10/shutil.py", line 256, in copyfile
    with open(dst, 'wb') as fdst:
PermissionError: [Errno 13] Permission denied: '/app/<USERNAME>/.config/<USERNAME>.ini.bak'
2023-05-02 17:32:16,674::ERROR::[config:901] Cannot create backup file for /app/<USERNAME>/.config/<USERNAME>.ini.bak
2023-05-02 17:32:16,674::INFO::[config:902] Traceback: 
Traceback (most recent call last):
  File "/app/<USERNAME>/<USERNAME>/config.py", line 897, in save_config
    shutil.copyfile(filename, bakname)
  File "/usr/lib/python3.10/shutil.py", line 256, in copyfile
    with open(dst, 'wb') as fdst:
PermissionError: [Errno 13] Permission denied: '/app/<USERNAME>/.config/<USERNAME>.ini.bak'
2023-05-02 17:32:46,682::ERROR::[config:901] Cannot create backup file for /app/<USERNAME>/.config/<USERNAME>.ini.bak
2023-05-02 17:32:46,682::INFO::[config:902] Traceback: 
Traceback (most recent call last):
  File "/app/<USERNAME>/<USERNAME>/config.py", line 897, in save_config
    shutil.copyfile(filename, bakname)
  File "/usr/lib/python3.10/shutil.py", line 256, in copyfile
    with open(dst, 'wb') as fdst:
PermissionError: [Errno 13] Permission denied: '/app/<USERNAME>/.config/<USERNAME>.ini.bak'
2023-05-02 17:33:16,689::ERROR::[config:901] Cannot create backup file for /app/<USERNAME>/.config/<USERNAME>.ini.bak
2023-05-02 17:33:16,690::INFO::[config:902] Traceback: 
Traceback (most recent call last):
  File "/app/<USERNAME>/<USERNAME>/config.py", line 897, in save_config
    shutil.copyfile(filename, bakname)
  File "/usr/lib/python3.10/shutil.py", line 256, in copyfile
    with open(dst, 'wb') as fdst:
PermissionError: [Errno 13] Permission denied: '/app/<USERNAME>/.config/<USERNAME>.ini.bak'
2023-05-02 17:33:46,696::ERROR::[config:901] Cannot create backup file for /app/<USERNAME>/.config/<USERNAME>.ini.bak
2023-05-02 17:33:46,697::INFO::[config:902] Traceback: 
Traceback (most recent call last):
  File "/app/<USERNAME>/<USERNAME>/config.py", line 897, in save_config
    shutil.copyfile(filename, bakname)
  File "/usr/lib/python3.10/shutil.py", line 256, in copyfile
    with open(dst, 'wb') as fdst:
PermissionError: [Errno 13] Permission denied: '/app/<USERNAME>/.config/<USERNAME>.ini.bak'
2023-05-02 17:34:16,704::ERROR::[config:901] Cannot create backup file for /app/<USERNAME>/.config/<USERNAME>.ini.bak
2023-05-02 17:34:16,705::INFO::[config:902] Traceback: 
Traceback (most recent call last):
  File "/app/<USERNAME>/<USERNAME>/config.py", line 897, in save_config
    shutil.copyfile(filename, bakname)
  File "/usr/lib/python3.10/shutil.py", line 256, in copyfile
    with open(dst, 'wb') as fdst:
PermissionError: [Errno 13] Permission denied: '/app/<USERNAME>/.config/<USERNAME>.ini.bak'
2023-05-02 17:34:46,711::ERROR::[config:901] Cannot create backup file for /app/<USERNAME>/.config/<USERNAME>.ini.bak
2023-05-02 17:34:46,712::INFO::[config:902] Traceback: 
Traceback (most recent call last):
  File "/app/<USERNAME>/<USERNAME>/config.py", line 897, in save_config
    shutil.copyfile(filename, bakname)
  File "/usr/lib/python3.10/shutil.py", line 256, in copyfile
    with open(dst, 'wb') as fdst:
PermissionError: [Errno 13] Permission denied: '/app/<USERNAME>/.config/<USERNAME>.ini.bak'
2023-05-02 17:35:16,719::ERROR::[config:901] Cannot create backup file for /app/<USERNAME>/.config/<USERNAME>.ini.bak
2023-05-02 17:35:16,719::INFO::[config:902] Traceback: 
Traceback (most recent call last):
  File "/app/<USERNAME>/<USERNAME>/config.py", line 897, in save_config
    shutil.copyfile(filename, bakname)
  File "/usr/lib/python3.10/shutil.py", line 256, in copyfile
    with open(dst, 'wb') as fdst:
PermissionError: [Errno 13] Permission denied: '/app/<USERNAME>/.config/<USERNAME>.ini.bak'
2023-05-02 17:35:46,726::ERROR::[config:901] Cannot create backup file for /app/<USERNAME>/.config/<USERNAME>.ini.bak
2023-05-02 17:35:46,726::INFO::[config:902] Traceback: 
Traceback (most recent call last):
  File "/app/<USERNAME>/<USERNAME>/config.py", line 897, in save_config
    shutil.copyfile(filename, bakname)
  File "/usr/lib/python3.10/shutil.py", line 256, in copyfile
    with open(dst, 'wb') as fdst:
PermissionError: [Errno 13] Permission denied: '/app/<USERNAME>/.config/<USERNAME>.ini.bak'
2023-05-02 17:36:16,764::ERROR::[config:901] Cannot create backup file for /app/<USERNAME>/.config/<USERNAME>.ini.bak
2023-05-02 17:36:16,765::INFO::[config:902] Traceback: 
Traceback (most recent call last):
  File "/app/<USERNAME>/<USERNAME>/config.py", line 897, in save_config
    shutil.copyfile(filename, bakname)
  File "/usr/lib/python3.10/shutil.py", line 256, in copyfile
    with open(dst, 'wb') as fdst:
PermissionError: [Errno 13] Permission denied: '/app/<USERNAME>/.config/<USERNAME>.ini.bak'
2023-05-02 17:36:46,771::ERROR::[config:901] Cannot create backup file for /app/<USERNAME>/.config/<USERNAME>.ini.bak
2023-05-02 17:36:46,771::INFO::[config:902] Traceback: 
Traceback (most recent call last):
  File "/app/<USERNAME>/<USERNAME>/config.py", line 897, in save_config
    shutil.copyfile(filename, bakname)
  File "/usr/lib/python3.10/shutil.py", line 256, in copyfile
    with open(dst, 'wb') as fdst:
PermissionError: [Errno 13] Permission denied: '/app/<USERNAME>/.config/<USERNAME>.ini.bak'
2023-05-02 17:37:16,777::ERROR::[config:901] Cannot create backup file for /app/<USERNAME>/.config/<USERNAME>.ini.bak
2023-05-02 17:37:16,778::INFO::[config:902] Traceback: 
Traceback (most recent call last):
  File "/app/<USERNAME>/<USERNAME>/config.py", line 897, in save_config
    shutil.copyfile(filename, bakname)
  File "/usr/lib/python3.10/shutil.py", line 256, in copyfile
    with open(dst, 'wb') as fdst:
PermissionError: [Errno 13] Permission denied: '/app/<USERNAME>/.config/<USERNAME>.ini.bak'
2023-05-02 17:37:46,785::ERROR::[config:901] Cannot create backup file for /app/<USERNAME>/.config/<USERNAME>.ini.bak
2023-05-02 17:37:46,785::INFO::[config:902] Traceback: 
Traceback (most recent call last):
  File "/app/<USERNAME>/<USERNAME>/config.py", line 897, in save_config
    shutil.copyfile(filename, bakname)
  File "/usr/lib/python3.10/shutil.py", line 256, in copyfile
    with open(dst, 'wb') as fdst:
PermissionError: [Errno 13] Permission denied: '/app/<USERNAME>/.config/<USERNAME>.ini.bak'
2023-05-02 17:38:16,794::ERROR::[config:901] Cannot create backup file for /app/<USERNAME>/.config/<USERNAME>.ini.bak
2023-05-02 17:38:16,794::INFO::[config:902] Traceback: 
Traceback (most recent call last):
  File "/app/<USERNAME>/<USERNAME>/config.py", line 897, in save_config
    shutil.copyfile(filename, bakname)
  File "/usr/lib/python3.10/shutil.py", line 256, in copyfile
    with open(dst, 'wb') as fdst:
PermissionError: [Errno 13] Permission denied: '/app/<USERNAME>/.config/<USERNAME>.ini.bak'
2023-05-02 17:38:46,801::ERROR::[config:901] Cannot create backup file for /app/<USERNAME>/.config/<USERNAME>.ini.bak
2023-05-02 17:38:46,802::INFO::[config:902] Traceback: 
Traceback (most recent call last):
  File "/app/<USERNAME>/<USERNAME>/config.py", line 897, in save_config
    shutil.copyfile(filename, bakname)
  File "/usr/lib/python3.10/shutil.py", line 256, in copyfile
    with open(dst, 'wb') as fdst:
PermissionError: [Errno 13] Permission denied: '/app/<USERNAME>/.config/<USERNAME>.ini.bak'
2023-05-02 17:39:16,809::ERROR::[config:901] Cannot create backup file for /app/<USERNAME>/.config/<USERNAME>.ini.bak
2023-05-02 17:39:16,809::INFO::[config:902] Traceback: 
Traceback (most recent call last):
  File "/app/<USERNAME>/<USERNAME>/config.py", line 897, in save_config
    shutil.copyfile(filename, bakname)
  File "/usr/lib/python3.10/shutil.py", line 256, in copyfile
    with open(dst, 'wb') as fdst:
PermissionError: [Errno 13] Permission denied: '/app/<USERNAME>/.config/<USERNAME>.ini.bak'
2023-05-02 17:39:46,816::ERROR::[config:901] Cannot create backup file for /app/<USERNAME>/.config/<USERNAME>.ini.bak
2023-05-02 17:39:46,817::INFO::[config:902] Traceback: 
Traceback (most recent call last):
  File "/app/<USERNAME>/<USERNAME>/config.py", line 897, in save_config
    shutil.copyfile(filename, bakname)
  File "/usr/lib/python3.10/shutil.py", line 256, in copyfile
    with open(dst, 'wb') as fdst:
PermissionError: [Errno 13] Permission denied: '/app/<USERNAME>/.config/<USERNAME>.ini.bak'
2023-05-02 17:40:16,823::ERROR::[config:901] Cannot create backup file for /app/<USERNAME>/.config/<USERNAME>.ini.bak
2023-05-02 17:40:16,823::INFO::[config:902] Traceback: 
Traceback (most recent call last):
  File "/app/<USERNAME>/<USERNAME>/config.py", line 897, in save_config
    shutil.copyfile(filename, bakname)
  File "/usr/lib/python3.10/shutil.py", line 256, in copyfile
    with open(dst, 'wb') as fdst:
PermissionError: [Errno 13] Permission denied: '/app/<USERNAME>/.config/<USERNAME>.ini.bak'
2023-05-02 17:40:46,830::ERROR::[config:901] Cannot create backup file for /app/<USERNAME>/.config/<USERNAME>.ini.bak
2023-05-02 17:40:46,830::INFO::[config:902] Traceback: 
Traceback (most recent call last):
  File "/app/<USERNAME>/<USERNAME>/config.py", line 897, in save_config
    shutil.copyfile(filename, bakname)
  File "/usr/lib/python3.10/shutil.py", line 256, in copyfile
    with open(dst, 'wb') as fdst:
PermissionError: [Errno 13] Permission denied: '/app/<USERNAME>/.config/<USERNAME>.ini.bak'
2023-05-02 17:41:16,870::ERROR::[config:901] Cannot create backup file for /app/<USERNAME>/.config/<USERNAME>.ini.bak
2023-05-02 17:41:16,870::INFO::[config:902] Traceback: 
Traceback (most recent call last):
  File "/app/<USERNAME>/<USERNAME>/config.py", line 897, in save_config
    shutil.copyfile(filename, bakname)
  File "/usr/lib/python3.10/shutil.py", line 256, in copyfile
    with open(dst, 'wb') as fdst:
PermissionError: [Errno 13] Permission denied: '/app/<USERNAME>/.config/<USERNAME>.ini.bak'
2023-05-02 17:41:46,877::ERROR::[config:901] Cannot create backup file for /app/<USERNAME>/.config/<USERNAME>.ini.bak
2023-05-02 17:41:46,878::INFO::[config:902] Traceback: 
Traceback (most recent call last):
  File "/app/<USERNAME>/<USERNAME>/config.py", line 897, in save_config
    shutil.copyfile(filename, bakname)
  File "/usr/lib/python3.10/shutil.py", line 256, in copyfile
    with open(dst, 'wb') as fdst:
PermissionError: [Errno 13] Permission denied: '/app/<USERNAME>/.config/<USERNAME>.ini.bak'
2023-05-02 17:42:16,885::ERROR::[config:901] Cannot create backup file for /app/<USERNAME>/.config/<USERNAME>.ini.bak
2023-05-02 17:42:16,885::INFO::[config:902] Traceback: 
Traceback (most recent call last):
  File "/app/<USERNAME>/<USERNAME>/config.py", line 897, in save_config
    shutil.copyfile(filename, bakname)
  File "/usr/lib/python3.10/shutil.py", line 256, in copyfile
    with open(dst, 'wb') as fdst:
PermissionError: [Errno 13] Permission denied: '/app/<USERNAME>/.config/<USERNAME>.ini.bak'
2023-05-02 17:42:46,891::ERROR::[config:901] Cannot create backup file for /app/<USERNAME>/.config/<USERNAME>.ini.bak
2023-05-02 17:42:46,891::INFO::[config:902] Traceback: 
Traceback (most recent call last):
  File "/app/<USERNAME>/<USERNAME>/config.py", line 897, in save_config
    shutil.copyfile(filename, bakname)
  File "/usr/lib/python3.10/shutil.py", line 256, in copyfile
    with open(dst, 'wb') as fdst:
PermissionError: [Errno 13] Permission denied: '/app/<USERNAME>/.config/<USERNAME>.ini.bak'
2023-05-02 17:43:16,898::ERROR::[config:901] Cannot create backup file for /app/<USERNAME>/.config/<USERNAME>.ini.bak
2023-05-02 17:43:16,899::INFO::[config:902] Traceback: 
Traceback (most recent call last):
  File "/app/<USERNAME>/<USERNAME>/config.py", line 897, in save_config
    shutil.copyfile(filename, bakname)
  File "/usr/lib/python3.10/shutil.py", line 256, in copyfile
    with open(dst, 'wb') as fdst:
PermissionError: [Errno 13] Permission denied: '/app/<USERNAME>/.config/<USERNAME>.ini.bak'
2023-05-02 17:43:46,906::ERROR::[config:901] Cannot create backup file for /app/<USERNAME>/.config/<USERNAME>.ini.bak
2023-05-02 17:43:46,906::INFO::[config:902] Traceback: 
Traceback (most recent call last):
  File "/app/<USERNAME>/<USERNAME>/config.py", line 897, in save_config
    shutil.copyfile(filename, bakname)
  File "/usr/lib/python3.10/shutil.py", line 256, in copyfile
    with open(dst, 'wb') as fdst:
PermissionError: [Errno 13] Permission denied: '/app/<USERNAME>/.config/<USERNAME>.ini.bak'
2023-05-02 17:44:16,913::ERROR::[config:901] Cannot create backup file for /app/<USERNAME>/.config/<USERNAME>.ini.bak
2023-05-02 17:44:16,913::INFO::[config:902] Traceback: 
Traceback (most recent call last):
  File "/app/<USERNAME>/<USERNAME>/config.py", line 897, in save_config
    shutil.copyfile(filename, bakname)
  File "/usr/lib/python3.10/shutil.py", line 256, in copyfile
    with open(dst, 'wb') as fdst:
PermissionError: [Errno 13] Permission denied: '/app/<USERNAME>/.config/<USERNAME>.ini.bak'
2023-05-02 17:44:46,920::ERROR::[config:901] Cannot create backup file for /app/<USERNAME>/.config/<USERNAME>.ini.bak
2023-05-02 17:44:46,920::INFO::[config:902] Traceback: 
Traceback (most recent call last):
  File "/app/<USERNAME>/<USERNAME>/config.py", line 897, in save_config
    shutil.copyfile(filename, bakname)
  File "/usr/lib/python3.10/shutil.py", line 256, in copyfile
    with open(dst, 'wb') as fdst:
PermissionError: [Errno 13] Permission denied: '/app/<USERNAME>/.config/<USERNAME>.ini.bak'
2023-05-02 17:45:16,927::ERROR::[config:901] Cannot create backup file for /app/<USERNAME>/.config/<USERNAME>.ini.bak
2023-05-02 17:45:16,928::INFO::[config:902] Traceback: 
Traceback (most recent call last):
  File "/app/<USERNAME>/<USERNAME>/config.py", line 897, in save_config
    shutil.copyfile(filename, bakname)
  File "/usr/lib/python3.10/shutil.py", line 256, in copyfile
    with open(dst, 'wb') as fdst:
PermissionError: [Errno 13] Permission denied: '/app/<USERNAME>/.config/<USERNAME>.ini.bak'
2023-05-02 17:45:46,935::ERROR::[config:901] Cannot create backup file for /app/<USERNAME>/.config/<USERNAME>.ini.bak
2023-05-02 17:45:46,936::INFO::[config:902] Traceback: 
Traceback (most recent call last):
  File "/app/<USERNAME>/<USERNAME>/config.py", line 897, in save_config
    shutil.copyfile(filename, bakname)
  File "/usr/lib/python3.10/shutil.py", line 256, in copyfile
    with open(dst, 'wb') as fdst:
PermissionError: [Errno 13] Permission denied: '/app/<USERNAME>/.config/<USERNAME>.ini.bak'
2023-05-02 17:46:16,972::ERROR::[config:901] Cannot create backup file for /app/<USERNAME>/.config/<USERNAME>.ini.bak
2023-05-02 17:46:16,972::INFO::[config:902] Traceback: 
Traceback (most recent call last):
  File "/app/<USERNAME>/<USERNAME>/config.py", line 897, in save_config
    shutil.copyfile(filename, bakname)
  File "/usr/lib/python3.10/shutil.py", line 256, in copyfile
    with open(dst, 'wb') as fdst:
PermissionError: [Errno 13] Permission denied: '/app/<USERNAME>/.config/<USERNAME>.ini.bak'
2023-05-02 17:46:46,977::ERROR::[config:901] Cannot create backup file for /app/<USERNAME>/.config/<USERNAME>.ini.bak
2023-05-02 17:46:46,977::INFO::[config:902] Traceback: 
Traceback (most recent call last):
  File "/app/<USERNAME>/<USERNAME>/config.py", line 897, in save_config
    shutil.copyfile(filename, bakname)
  File "/usr/lib/python3.10/shutil.py", line 256, in copyfile
    with open(dst, 'wb') as fdst:
PermissionError: [Errno 13] Permission denied: '/app/<USERNAME>/.config/<USERNAME>.ini.bak'
2023-05-02 17:47:16,984::ERROR::[config:901] Cannot create backup file for /app/<USERNAME>/.config/<USERNAME>.ini.bak
2023-05-02 17:47:16,984::INFO::[config:902] Traceback: 
Traceback (most recent call last):
  File "/app/<USERNAME>/<USERNAME>/config.py", line 897, in save_config
    shutil.copyfile(filename, bakname)
  File "/usr/lib/python3.10/shutil.py", line 256, in copyfile
    with open(dst, 'wb') as fdst:
PermissionError: [Errno 13] Permission denied: '/app/<USERNAME>/.config/<USERNAME>.ini.bak'
2023-05-02 17:47:46,991::ERROR::[config:901] Cannot create backup file for /app/<USERNAME>/.config/<USERNAME>.ini.bak
2023-05-02 17:47:46,991::INFO::[config:902] Traceback: 
Traceback (most recent call last):
  File "/app/<USERNAME>/<USERNAME>/config.py", line 897, in save_config
    shutil.copyfile(filename, bakname)
  File "/usr/lib/python3.10/shutil.py", line 256, in copyfile
    with open(dst, 'wb') as fdst:
PermissionError: [Errno 13] Permission denied: '/app/<USERNAME>/.config/<USERNAME>.ini.bak'
2023-05-02 17:48:16,998::ERROR::[config:901] Cannot create backup file for /app/<USERNAME>/.config/<USERNAME>.ini.bak
2023-05-02 17:48:16,998::INFO::[config:902] Traceback: 
Traceback (most recent call last):
  File "/app/<USERNAME>/<USERNAME>/config.py", line 897, in save_config
    shutil.copyfile(filename, bakname)
  File "/usr/lib/python3.10/shutil.py", line 256, in copyfile
    with open(dst, 'wb') as fdst:
PermissionError: [Errno 13] Permission denied: '/app/<USERNAME>/.config/<USERNAME>.ini.bak'
2023-05-02 17:48:47,005::ERROR::[config:901] Cannot create backup file for /app/<USERNAME>/.config/<USERNAME>.ini.bak
2023-05-02 17:48:47,006::INFO::[config:902] Traceback: 
Traceback (most recent call last):
  File "/app/<USERNAME>/<USERNAME>/config.py", line 897, in save_config
    shutil.copyfile(filename, bakname)
  File "/usr/lib/python3.10/shutil.py", line 256, in copyfile
    with open(dst, 'wb') as fdst:
PermissionError: [Errno 13] Permission denied: '/app/<USERNAME>/.config/<USERNAME>.ini.bak'
2023-05-02 17:49:17,013::ERROR::[config:901] Cannot create backup file for /app/<USERNAME>/.config/<USERNAME>.ini.bak
2023-05-02 17:49:17,013::INFO::[config:902] Traceback: 
Traceback (most recent call last):
  File "/app/<USERNAME>/<USERNAME>/config.py", line 897, in save_config
    shutil.copyfile(filename, bakname)
  File "/usr/lib/python3.10/shutil.py", line 256, in copyfile
    with open(dst, 'wb') as fdst:
PermissionError: [Errno 13] Permission denied: '/app/<USERNAME>/.config/<USERNAME>.ini.bak'
2023-05-02 17:49:47,019::ERROR::[config:901] Cannot create backup file for /app/<USERNAME>/.config/<USERNAME>.ini.bak
2023-05-02 17:49:47,020::INFO::[config:902] Traceback: 
Traceback (most recent call last):
  File "/app/<USERNAME>/<USERNAME>/config.py", line 897, in save_config
    shutil.copyfile(filename, bakname)
  File "/usr/lib/python3.10/shutil.py", line 256, in copyfile
    with open(dst, 'wb') as fdst:
PermissionError: [Errno 13] Permission denied: '/app/<USERNAME>/.config/<USERNAME>.ini.bak'
2023-05-02 17:50:17,027::ERROR::[config:901] Cannot create backup file for /app/<USERNAME>/.config/<USERNAME>.ini.bak
2023-05-02 17:50:17,027::INFO::[config:902] Traceback: 
Traceback (most recent call last):
  File "/app/<USERNAME>/<USERNAME>/config.py", line 897, in save_config
    shutil.copyfile(filename, bakname)
  File "/usr/lib/python3.10/shutil.py", line 256, in copyfile
    with open(dst, 'wb') as fdst:
PermissionError: [Errno 13] Permission denied: '/app/<USERNAME>/.config/<USERNAME>.ini.bak'
2023-05-02 17:50:47,034::ERROR::[config:901] Cannot create backup file for /app/<USERNAME>/.config/<USERNAME>.ini.bak
2023-05-02 17:50:47,035::INFO::[config:902] Traceback: 
Traceback (most recent call last):
  File "/app/<USERNAME>/<USERNAME>/config.py", line 897, in save_config
    shutil.copyfile(filename, bakname)
  File "/usr/lib/python3.10/shutil.py", line 256, in copyfile
    with open(dst, 'wb') as fdst:
PermissionError: [Errno 13] Permission denied: '/app/<USERNAME>/.config/<USERNAME>.ini.bak'
2023-05-02 17:51:17,071::ERROR::[config:901] Cannot create backup file for /app/<USERNAME>/.config/<USERNAME>.ini.bak
2023-05-02 17:51:17,071::INFO::[config:902] Traceback: 
Traceback (most recent call last):
  File "/app/<USERNAME>/<USERNAME>/config.py", line 897, in save_config
    shutil.copyfile(filename, bakname)
  File "/usr/lib/python3.10/shutil.py", line 256, in copyfile
    with open(dst, 'wb') as fdst:
PermissionError: [Errno 13] Permission denied: '/app/<USERNAME>/.config/<USERNAME>.ini.bak'
2023-05-02 17:51:47,077::ERROR::[config:901] Cannot create backup file for /app/<USERNAME>/.config/<USERNAME>.ini.bak
2023-05-02 17:51:47,078::INFO::[config:902] Traceback: 
Traceback (most recent call last):
  File "/app/<USERNAME>/<USERNAME>/config.py", line 897, in save_config
    shutil.copyfile(filename, bakname)
  File "/usr/lib/python3.10/shutil.py", line 256, in copyfile
    with open(dst, 'wb') as fdst:
PermissionError: [Errno 13] Permission denied: '/app/<USERNAME>/.config/<USERNAME>.ini.bak'
2023-05-02 17:52:17,087::ERROR::[config:901] Cannot create backup file for /app/<USERNAME>/.config/<USERNAME>.ini.bak
2023-05-02 17:52:17,088::INFO::[config:902] Traceback: 
Traceback (most recent call last):
  File "/app/<USERNAME>/<USERNAME>/config.py", line 897, in save_config
    shutil.copyfile(filename, bakname)
  File "/usr/lib/python3.10/shutil.py", line 256, in copyfile
    with open(dst, 'wb') as fdst:
PermissionError: [Errno 13] Permission denied: '/app/<USERNAME>/.config/<USERNAME>.ini.bak'
2023-05-02 17:52:47,095::ERROR::[config:901] Cannot create backup file for /app/<USERNAME>/.config/<USERNAME>.ini.bak
2023-05-02 17:52:47,095::INFO::[config:902] Traceback: 
Traceback (most recent call last):
  File "/app/<USERNAME>/<USERNAME>/config.py", line 897, in save_config
    shutil.copyfile(filename, bakname)
  File "/usr/lib/python3.10/shutil.py", line 256, in copyfile
    with open(dst, 'wb') as fdst:
PermissionError: [Errno 13] Permission denied: '/app/<USERNAME>/.config/<USERNAME>.ini.bak'
2023-05-02 17:53:17,102::ERROR::[config:901] Cannot create backup file for /app/<USERNAME>/.config/<USERNAME>.ini.bak
2023-05-02 17:53:17,102::INFO::[config:902] Traceback: 
Traceback (most recent call last):
  File "/app/<USERNAME>/<USERNAME>/config.py", line 897, in save_config
    shutil.copyfile(filename, bakname)
  File "/usr/lib/python3.10/shutil.py", line 256, in copyfile
    with open(dst, 'wb') as fdst:
PermissionError: [Errno 13] Permission denied: '/app/<USERNAME>/.config/<USERNAME>.ini.bak'
2023-05-02 17:53:47,109::ERROR::[config:901] Cannot create backup file for /app/<USERNAME>/.config/<USERNAME>.ini.bak
2023-05-02 17:53:47,110::INFO::[config:902] Traceback: 
Traceback (most recent call last):
  File "/app/<USERNAME>/<USERNAME>/config.py", line 897, in save_config
    shutil.copyfile(filename, bakname)
  File "/usr/lib/python3.10/shutil.py", line 256, in copyfile
    with open(dst, 'wb') as fdst:
PermissionError: [Errno 13] Permission denied: '/app/<USERNAME>/.config/<USERNAME>.ini.bak'
2023-05-02 17:54:17,117::ERROR::[config:901] Cannot create backup file for /app/<USERNAME>/.config/<USERNAME>.ini.bak
2023-05-02 17:54:17,118::INFO::[config:902] Traceback: 
Traceback (most recent call last):
  File "/app/<USERNAME>/<USERNAME>/config.py", line 897, in save_config
    shutil.copyfile(filename, bakname)
  File "/usr/lib/python3.10/shutil.py", line 256, in copyfile
    with open(dst, 'wb') as fdst:
PermissionError: [Errno 13] Permission denied: '/app/<USERNAME>/.config/<USERNAME>.ini.bak'
2023-05-02 17:54:47,125::ERROR::[config:901] Cannot create backup file for /app/<USERNAME>/.config/<USERNAME>.ini.bak
2023-05-02 17:54:47,126::INFO::[config:902] Traceback: 
Traceback (most recent call last):
  File "/app/<USERNAME>/<USERNAME>/config.py", line 897, in save_config
    shutil.copyfile(filename, bakname)
  File "/usr/lib/python3.10/shutil.py", line 256, in copyfile
    with open(dst, 'wb') as fdst:
PermissionError: [Errno 13] Permission denied: '/app/<USERNAME>/.config/<USERNAME>.ini.bak'
2023-05-02 17:55:17,133::ERROR::[config:901] Cannot create backup file for /app/<USERNAME>/.config/<USERNAME>.ini.bak
2023-05-02 17:55:17,133::INFO::[config:902] Traceback: 
Traceback (most recent call last):
  File "/app/<USERNAME>/<USERNAME>/config.py", line 897, in save_config
    shutil.copyfile(filename, bakname)
  File "/usr/lib/python3.10/shutil.py", line 256, in copyfile
    with open(dst, 'wb') as fdst:
PermissionError: [Errno 13] Permission denied: '/app/<USERNAME>/.config/<USERNAME>.ini.bak'
2023-05-02 17:55:47,140::ERROR::[config:901] Cannot create backup file for /app/<USERNAME>/.config/<USERNAME>.ini.bak
2023-05-02 17:55:47,141::INFO::[config:902] Traceback: 
Traceback (most recent call last):
  File "/app/<USERNAME>/<USERNAME>/config.py", line 897, in save_config
    shutil.copyfile(filename, bakname)
  File "/usr/lib/python3.10/shutil.py", line 256, in copyfile
    with open(dst, 'wb') as fdst:
PermissionError: [Errno 13] Permission denied: '/app/<USERNAME>/.config/<USERNAME>.ini.bak'
2023-05-02 17:56:17,178::ERROR::[config:901] Cannot create backup file for /app/<USERNAME>/.config/<USERNAME>.ini.bak
2023-05-02 17:56:17,178::INFO::[config:902] Traceback: 
Traceback (most recent call last):
  File "/app/<USERNAME>/<USERNAME>/config.py", line 897, in save_config
    shutil.copyfile(filename, bakname)
  File "/usr/lib/python3.10/shutil.py", line 256, in copyfile
    with open(dst, 'wb') as fdst:
PermissionError: [Errno 13] Permission denied: '/app/<USERNAME>/.config/<USERNAME>.ini.bak'
2023-05-02 17:56:47,185::ERROR::[config:901] Cannot create backup file for /app/<USERNAME>/.config/<USERNAME>.ini.bak
2023-05-02 17:56:47,186::INFO::[config:902] Traceback: 
Traceback (most recent call last):
  File "/app/<USERNAME>/<USERNAME>/config.py", line 897, in save_config
    shutil.copyfile(filename, bakname)
  File "/usr/lib/python3.10/shutil.py", line 256, in copyfile
    with open(dst, 'wb') as fdst:
PermissionError: [Errno 13] Permission denied: '/app/<USERNAME>/.config/<USERNAME>.ini.bak'
2023-05-02 17:57:17,193::ERROR::[config:901] Cannot create backup file for /app/<USERNAME>/.config/<USERNAME>.ini.bak
2023-05-02 17:57:17,194::INFO::[config:902] Traceback: 
Traceback (most recent call last):
  File "/app/<USERNAME>/<USERNAME>/config.py", line 897, in save_config
    shutil.copyfile(filename, bakname)
  File "/usr/lib/python3.10/shutil.py", line 256, in copyfile
    with open(dst, 'wb') as fdst:
PermissionError: [Errno 13] Permission denied: '/app/<USERNAME>/.config/<USERNAME>.ini.bak'
2023-05-02 17:57:47,201::ERROR::[config:901] Cannot create backup file for /app/<USERNAME>/.config/<USERNAME>.ini.bak
2023-05-02 17:57:47,201::INFO::[config:902] Traceback: 
Traceback (most recent call last):
  File "/app/<USERNAME>/<USERNAME>/config.py", line 897, in save_config
    shutil.copyfile(filename, bakname)
  File "/usr/lib/python3.10/shutil.py", line 256, in copyfile
    with open(dst, 'wb') as fdst:
PermissionError: [Errno 13] Permission denied: '/app/<USERNAME>/.config/<USERNAME>.ini.bak'
2023-05-02 17:58:17,208::ERROR::[config:901] Cannot create backup file for /app/<USERNAME>/.config/<USERNAME>.ini.bak
2023-05-02 17:58:17,209::INFO::[config:902] Traceback: 
Traceback (most recent call last):
  File "/app/<USERNAME>/<USERNAME>/config.py", line 897, in save_config
    shutil.copyfile(filename, bakname)
  File "/usr/lib/python3.10/shutil.py", line 256, in copyfile
    with open(dst, 'wb') as fdst:
PermissionError: [Errno 13] Permission denied: '/app/<USERNAME>/.config/<USERNAME>.ini.bak'
2023-05-02 17:58:47,215::ERROR::[config:901] Cannot create backup file for /app/<USERNAME>/.config/<USERNAME>.ini.bak
2023-05-02 17:58:47,216::INFO::[config:902] Traceback: 
Traceback (most recent call last):
  File "/app/<USERNAME>/<USERNAME>/config.py", line 897, in save_config
    shutil.copyfile(filename, bakname)
  File "/usr/lib/python3.10/shutil.py", line 256, in copyfile
    with open(dst, 'wb') as fdst:
PermissionError: [Errno 13] Permission denied: '/app/<USERNAME>/.config/<USERNAME>.ini.bak'
2023-05-02 17:59:17,223::ERROR::[config:901] Cannot create backup file for /app/<USERNAME>/.config/<USERNAME>.ini.bak
2023-05-02 17:59:17,223::INFO::[config:902] Traceback: 
Traceback (most recent call last):
  File "/app/<USERNAME>/<USERNAME>/config.py", line 897, in save_config
    shutil.copyfile(filename, bakname)
  File "/usr/lib/python3.10/shutil.py", line 256, in copyfile
    with open(dst, 'wb') as fdst:
PermissionError: [Errno 13] Permission denied: '/app/<USERNAME>/.config/<USERNAME>.ini.bak'
2023-05-02 17:59:47,231::ERROR::[config:901] Cannot create backup file for /app/<USERNAME>/.config/<USERNAME>.ini.bak
2023-05-02 17:59:47,231::INFO::[config:902] Traceback: 
Traceback (most recent call last):
  File "/app/<USERNAME>/<USERNAME>/config.py", line 897, in save_config
    shutil.copyfile(filename, bakname)
  File "/usr/lib/python3.10/shutil.py", line 256, in copyfile
    with open(dst, 'wb') as fdst:
PermissionError: [Errno 13] Permission denied: '/app/<USERNAME>/.config/<USERNAME>.ini.bak'
2023-05-02 18:00:17,238::ERROR::[config:901] Cannot create backup file for /app/<USERNAME>/.config/<USERNAME>.ini.bak
2023-05-02 18:00:17,239::INFO::[config:902] Traceback: 
Traceback (most recent call last):
  File "/app/<USERNAME>/<USERNAME>/config.py", line 897, in save_config
    shutil.copyfile(filename, bakname)
  File "/usr/lib/python3.10/shutil.py", line 256, in copyfile
    with open(dst, 'wb') as fdst:
PermissionError: [Errno 13] Permission denied: '/app/<USERNAME>/.config/<USERNAME>.ini.bak'
2023-05-02 18:00:47,248::ERROR::[config:901] Cannot create backup file for /app/<USERNAME>/.config/<USERNAME>.ini.bak
2023-05-02 18:00:47,248::INFO::[config:902] Traceback: 
Traceback (most recent call last):
  File "/app/<USERNAME>/<USERNAME>/config.py", line 897, in save_config
    shutil.copyfile(filename, bakname)
  File "/usr/lib/python3.10/shutil.py", line 256, in copyfile
    with open(dst, 'wb') as fdst:
PermissionError: [Errno 13] Permission denied: '/app/<USERNAME>/.config/<USERNAME>.ini.bak'
2023-05-02 18:01:17,284::ERROR::[config:901] Cannot create backup file for /app/<USERNAME>/.config/<USERNAME>.ini.bak
2023-05-02 18:01:17,285::INFO::[config:902] Traceback: 
Traceback (most recent call last):
  File "/app/<USERNAME>/<USERNAME>/config.py", line 897, in save_config
    shutil.copyfile(filename, bakname)
  File "/usr/lib/python3.10/shutil.py", line 256, in copyfile
    with open(dst, 'wb') as fdst:
PermissionError: [Errno 13] Permission denied: '/app/<USERNAME>/.config/<USERNAME>.ini.bak'
2023-05-02 18:01:35,698::ERROR::[config:901] Cannot create backup file for /app/<USERNAME>/.config/<USERNAME>.ini.bak
2023-05-02 18:01:35,699::INFO::[config:902] Traceback: 
Traceback (most recent call last):
  File "/app/<USERNAME>/<USERNAME>/config.py", line 897, in save_config
    shutil.copyfile(filename, bakname)
  File "/usr/lib/python3.10/shutil.py", line 256, in copyfile
    with open(dst, 'wb') as fdst:
PermissionError: [Errno 13] Permission denied: '/app/<USERNAME>/.config/<USERNAME>.ini.bak'
2023-05-02 18:01:38,355::DEBUG::[interface:133] Request GET /api from 10.8.0.18 [Mozilla/5.0 (X11; Linux x86_64; rv:102.0) Gecko/20100101 Firefox/102.0] {'mode': 'queue', 'start': '0', 'limit': '20', 'output': 'json', 'apikey':<APIKEY>', '_': '1683047257425'}
2023-05-02 18:01:38,357::DEBUG::[interface:133] Request GET /api from 10.8.0.18 [Mozilla/5.0 (X11; Linux x86_64; rv:102.0) Gecko/20100101 Firefox/102.0] {'mode': 'history', 'failed_only': '0', 'start': '0', 'limit': '10', 'last_history_update': '1', 'output': 'json', 'apikey':<APIKEY>', '_': '1683047257426'}
2023-05-02 18:01:38,940::DEBUG::[interface:133] Request GET /api from 10.8.0.18 [Mozilla/5.0 (X11; Linux x86_64; rv:102.0) Gecko/20100101 Firefox/102.0] {'mode': 'set_config', 'section': 'logging', 'keyword': 'log_level', 'value': '1', 'output': 'json', 'apikey':<APIKEY>', '_': '1683047257427'}
2023-05-02 18:01:38,944::ERROR::[config:901] Cannot create backup file for /app/<USERNAME>/.config/<USERNAME>.ini.bak
2023-05-02 18:01:38,944::INFO::[config:902] Traceback: 
Traceback (most recent call last):
  File "/app/<USERNAME>/<USERNAME>/config.py", line 897, in save_config
    shutil.copyfile(filename, bakname)
  File "/usr/lib/python3.10/shutil.py", line 256, in copyfile
    with open(dst, 'wb') as fdst:
PermissionError: [Errno 13] Permission denied: '/app/<USERNAME>/.config/<USERNAME>.ini.bak'
2023-05-02 18:01:39,374::DEBUG::[interface:133] Request GET /api from 10.8.0.18 [Mozilla/5.0 (X11; Linux x86_64; rv:102.0) Gecko/20100101 Firefox/102.0] {'mode': 'queue', 'start': '0', 'limit': '20', 'output': 'json', 'apikey':<APIKEY>', '_': '1683047257428'}
2023-05-02 18:01:39,376::DEBUG::[interface:133] Request GET /api from 10.8.0.18 [Mozilla/5.0 (X11; Linux x86_64; rv:102.0) Gecko/20100101 Firefox/102.0] {'mode': 'history', 'failed_only': '0', 'start': '0', 'limit': '10', 'last_history_update': '1', 'output': 'json', 'apikey':<APIKEY>', '_': '1683047257429'}
2023-05-02 18:01:40,392::DEBUG::[interface:133] Request GET /api from 10.8.0.18 [Mozilla/5.0 (X11; Linux x86_64; rv:102.0) Gecko/20100101 Firefox/102.0] {'mode': 'queue', 'start': '0', 'limit': '20', 'output': 'json', 'apikey':<APIKEY>', '_': '1683047257430'}
2023-05-02 18:01:40,394::DEBUG::[interface:133] Request GET /api from 10.8.0.18 [Mozilla/5.0 (X11; Linux x86_64; rv:102.0) Gecko/20100101 Firefox/102.0] {'mode': 'history', 'failed_only': '0', 'start': '0', 'limit': '10', 'last_history_update': '1', 'output': 'json', 'apikey':<APIKEY>', '_': '1683047257431'}
2023-05-02 18:01:40,647::DEBUG::[interface:133] Request GET /api from 10.8.0.18 [Mozilla/5.0 (X11; Linux x86_64; rv:102.0) Gecko/20100101 Firefox/102.0] {'mode': 'status', 'skip_dashboard': '1', 'calculate_performance': '0', 'output': 'json', 'apikey':<APIKEY>', '_': '1683047257432'}
2023-05-02 18:01:40,804::DEBUG::[interface:133] Request GET /api from 10.8.0.18 [Mozilla/5.0 (X11; Linux x86_64; rv:102.0) Gecko/20100101 Firefox/102.0] {'mode': 'status', 'skip_dashboard': '1', 'calculate_performance': '0', 'output': 'json', 'apikey':<APIKEY>', '_': '1683047257433'}
2023-05-02 18:01:47,291::ERROR::[config:901] Cannot create backup file for /app/<USERNAME>/.config/<USERNAME>.ini.bak
2023-05-02 18:01:47,292::INFO::[config:902] Traceback: 
Traceback (most recent call last):
  File "/app/<USERNAME>/<USERNAME>/config.py", line 897, in save_config
    shutil.copyfile(filename, bakname)
  File "/usr/lib/python3.10/shutil.py", line 256, in copyfile
    with open(dst, 'wb') as fdst:
PermissionError: [Errno 13] Permission denied: '/app/<USERNAME>/.config/<USERNAME>.ini.bak'
2023-05-02 18:01:48,002::ERROR::[config:901] Cannot create backup file for /app/<USERNAME>/.config/<USERNAME>.ini.bak
2023-05-02 18:01:48,002::INFO::[config:902] Traceback: 
Traceback (most recent call last):
  File "/app/<USERNAME>/<USERNAME>/config.py", line 897, in save_config
    shutil.copyfile(filename, bakname)
  File "/usr/lib/python3.10/shutil.py", line 256, in copyfile
    with open(dst, 'wb') as fdst:
PermissionError: [Errno 13] Permission denied: '/app/<USERNAME>/.config/<USERNAME>.ini.bak'
__version__ = 19
__encoding__ = utf-8
[misc]
pre_script = None
queue_complete = ""
queue_complete_pers = 0
bandwidth_perc = 1
refresh_rate = 0
interface_settings = ""
queue_limit = 20
config_lock = 0
fixed_ports = 1
sched_converted = 0
notified_new_skin = 0
direct_unpack_tested = 1
check_new_rel = 1
auto_browser = 1
language = en
enable_https_verification = 1
host = 0.0.0.0
port = 8080
https_port = ""
username=<USER>
password=<PASSWORD>
bandwidth_max = ""
cache_limit = 1G
web_dir = Glitter
web_color = Night
https_cert = server.cert
https_key = server.key
https_chain = ""
enable_https = 0
inet_exposure = 0
api_key = <HASH>21aed29
nzb_key = <HASH>4d8e8df
socks5_proxy_url = ""
permissions = ""
download_dir = /tmp/Downloads/incomplete
download_free = ""
complete_dir = /tmp/Downloads/complete
complete_free = ""
fulldisk_autoresume = 0
script_dir = ""
nzb_backup_dir = ""
admin_dir = /tmp/admin
backup_dir = ""
dirscan_dir = ""
dirscan_speed = 5
password_file = ""
log_dir = /var/log/<USERNAME>
max_art_tries = 3
load_balancing = 2
top_only = 0
sfv_check = 1
script_can_fail = 0
enable_recursive = 1
flat_unpack = 0
par_option = ""
pre_check = 0
nice = ""
win_process_prio = 3
ionice = ""
fail_hopeless_jobs = 1
fast_fail = 1
auto_disconnect = 1
no_dupes = 0
no_series_dupes = 0
series_propercheck = 1
pause_on_pwrar = 1
ignore_samples = 0
deobfuscate_final_filenames = 0
auto_sort = ""
direct_unpack = 0
propagation_delay = 0
folder_rename = 1
replace_spaces = 0
replace_underscores = 0
replace_dots = 0
safe_postproc = 1
pause_on_post_processing = 0
enable_all_par = 0
sanitize_safe = 0
cleanup_list = ,
unwanted_extensions = ,
action_on_unwanted_extensions = 0
unwanted_extensions_mode = 0
new_nzb_on_failure = 0
history_retention = 0
quota_size = ""
quota_day = ""
quota_resume = 0
quota_period = m
enable_tv_sorting = 0
tv_sort_string = ""
tv_categories = tv,
enable_movie_sorting = 0
movie_sort_string = ""
movie_sort_extra = -cd%1
movie_categories = movies,
enable_date_sorting = 0
date_sort_string = ""
date_categories = tv,
schedlines = ,
rss_rate = 60
ampm = 0
start_paused = 0
preserve_paused_state = 0
enable_par_cleanup = 1
process_unpacked_par2 = 1
enable_unrar = 1
enable_unzip = 1
enable_7zip = 1
enable_filejoin = 1
enable_tsjoin = 1
overwrite_files = 0
ignore_unrar_dates = 0
backup_for_duplicates = 1
empty_postproc = 0
wait_for_dfolder = 0
rss_filenames = 0
api_logging = 1
html_login = 0
warn_dupl_jobs = 1
helpful_warnings = 1
keep_awake = 1
tray_icon = 1
allow_incomplete_nzb = 0
enable_broadcast = 1
ipv6_hosting = 0
api_warnings = 1
no_penalties = 0
x_frame_options = 1
allow_old_ssl_tls = 0
rss_odd_titles = nzbindex.nl/, nzbindex.com/, nzbclub.com/
quick_check_ext_ignore = nfo, sfv, srr
req_completion_rate = 100.2
selftest_host = self-test.<USERNAME>.org
movie_rename_limit = 100M
episode_rename_limit = 20M
size_limit = 0
direct_unpack_threads = 3
history_limit = 10
wait_ext_drive = 5
max_foldername_length = 246
nomedia_marker = ""
ipv6_servers = 0
url_base = /<USERNAME>
host_whitelist = 17985f3c0b16,
local_ranges = ,
max_url_retries = 10
downloader_sleep_time = 10
num_simd_decoders = 2
ssdp_broadcast_interval = 15
ext_rename_ignore = ,
email_server = ""
email_to = <REMOVED>
email_from = ""
email_account = <REMOVED>
email_pwd = <REMOVED>
email_endjob = 0
email_full = 0
email_dir = ""
email_rss = 0
email_cats = *,
[logging]
log_level = 1
max_log_size = 5242880
log_backups = 5
[ncenter]
ncenter_enable = 0
ncenter_cats = *,
ncenter_prio_startup = 1
ncenter_prio_download = 0
ncenter_prio_pause_resume = 0
ncenter_prio_pp = 0
ncenter_prio_complete = 1
ncenter_prio_failed = 1
ncenter_prio_disk_full = 1
ncenter_prio_new_login = 0
ncenter_prio_warning = 0
ncenter_prio_error = 0
ncenter_prio_queue_done = 1
ncenter_prio_other = 1
[acenter]
acenter_enable = 0
acenter_cats = *,
acenter_prio_startup = 0
acenter_prio_download = 0
acenter_prio_pause_resume = 0
acenter_prio_pp = 0
acenter_prio_complete = 1
acenter_prio_failed = 1
acenter_prio_disk_full = 1
acenter_prio_new_login = 0
acenter_prio_warning = 0
acenter_prio_error = 0
acenter_prio_queue_done = 1
acenter_prio_other = 1
[ntfosd]
ntfosd_enable = 1
ntfosd_cats = *,
ntfosd_prio_startup = 1
ntfosd_prio_download = 0
ntfosd_prio_pause_resume = 0
ntfosd_prio_pp = 0
ntfosd_prio_complete = 1
ntfosd_prio_failed = 1
ntfosd_prio_disk_full = 1
ntfosd_prio_new_login = 0
ntfosd_prio_warning = 0
ntfosd_prio_error = 0
ntfosd_prio_queue_done = 1
ntfosd_prio_other = 1
[prowl]
prowl_enable = 0
prowl_cats = *,
prowl_apikey = <REMOVED>
prowl_prio_startup = -3
prowl_prio_download = -3
prowl_prio_pause_resume = -3
prowl_prio_pp = -3
prowl_prio_complete = 0
prowl_prio_failed = 1
prowl_prio_disk_full = 1
prowl_prio_new_login = -3
prowl_prio_warning = -3
prowl_prio_error = -3
prowl_prio_queue_done = 0
prowl_prio_other = 0
[pushover]
pushover_token = <REMOVED>
pushover_userkey = <REMOVED>
pushover_device = ""
pushover_emergency_expire = 3600
pushover_emergency_retry = 60
pushover_enable = 0
pushover_cats = *,
pushover_prio_startup = -3
pushover_prio_download = -2
pushover_prio_pause_resume = -2
pushover_prio_pp = -3
pushover_prio_complete = -1
pushover_prio_failed = -1
pushover_prio_disk_full = 1
pushover_prio_new_login = -3
pushover_prio_warning = 1
pushover_prio_error = 1
pushover_prio_queue_done = -1
pushover_prio_other = -1
[pushbullet]
pushbullet_enable = 0
pushbullet_cats = *,
pushbullet_apikey = <REMOVED>
pushbullet_device = ""
pushbullet_prio_startup = 0
pushbullet_prio_download = 0
pushbullet_prio_pause_resume = 0
pushbullet_prio_pp = 0
pushbullet_prio_complete = 1
pushbullet_prio_failed = 1
pushbullet_prio_disk_full = 1
pushbullet_prio_new_login = 0
pushbullet_prio_warning = 0
pushbullet_prio_error = 0
pushbullet_prio_queue_done = 0
pushbullet_prio_other = 1
[nscript]
nscript_enable = 0
nscript_cats = *,
nscript_script = ""
nscript_parameters = ""
nscript_prio_startup = 1
nscript_prio_download = 0
nscript_prio_pause_resume = 0
nscript_prio_pp = 0
nscript_prio_complete = 1
nscript_prio_failed = 1
nscript_prio_disk_full = 1
nscript_prio_new_login = 0
nscript_prio_warning = 0
nscript_prio_error = 0
nscript_prio_queue_done = 1
nscript_prio_other = 1
[servers]
[[news.eweka.nl.local]]
name = news.eweka.nl.local
displayname = news.eweka.nl
host = news.eweka.nl.local
port = 119
timeout = 60
username=<USER>
password=<PASSWORD>
connections = 50
ssl = 0
ssl_verify = 2
ssl_ciphers = ""
enable = 1
required = 0
optional = 0
retention = 0
expire_date = ""
quota = ""
usage_at_start = 0
send_group = 0
priority = 0
notes = ""
[[news.newsdemon.com.local]]
name = news.newsdemon.com.local
displayname = news.newsdemon.com
host = news.newsdemon.com.local
port = 563
timeout = 60
username=<USER>
password=<PASSWORD>
connections = 50
ssl = 1
ssl_verify = 2
ssl_ciphers = ""
enable = 1
required = 0
optional = 0
retention = 0
expire_date = ""
quota = ""
usage_at_start = 0
send_group = 0
priority = 0
notes = ""
[[news4.usenet.farm.local]]
name = news4.usenet.farm.local
displayname = news4.usenet.farm
host = news4.usenet.farm.local
port = 563
timeout = 60
username=<USER>
password=<PASSWORD>
connections = 40
ssl = 1
ssl_verify = 2
ssl_ciphers = ""
enable = 1
required = 0
optional = 0
retention = 0
expire_date = ""
quota = ""
usage_at_start = 0
send_group = 0
priority = 0
notes = ""
[[news.newshosting.com.local]]
name = news.newshosting.com.local
displayname = news.newshosting.com
host = news.newshosting.com.local
port = 563
timeout = 60
username=<USER>
password=<PASSWORD>
connections = 45
ssl = 1
ssl_verify = 2
ssl_ciphers = ""
enable = 1
required = 0
optional = 0
retention = 0
expire_date = ""
quota = ""
usage_at_start = 0
send_group = 0
priority = 1
notes = ""
[categories]
[[*]]
name = *
order = 0
pp = 3
script = None
dir = ""
newzbin = ""
priority = 0
[[movies]]
name = movies
order = 0
pp = ""
script = Default
dir = ""
newzbin = ""
priority = -100
[[tv]]
name = tv
order = 0
pp = ""
script = Default
dir = ""
newzbin = ""
priority = -100
[[audio]]
name = audio
order = 0
pp = ""
script = Default
dir = ""
newzbin = ""
priority = -100
[[software]]
name = software
order = 0
pp = ""
script = Default
dir = ""
newzbin = ""
priority = -100
